2020-08-25 13:17:15,680 [INFO]: #  **** 从Excel导入用例套件成功 ****
2020-08-25 13:17:15,680 [INFO]: #  **** 解析用例成功 ****
2020-08-25 13:17:15,680 [INFO]: #  -------- Run The TestCase：test-1 验证码登录运营中台
2020-08-25 13:17:15,680 [ERROR]: #  用例test-1:验证码登录运营中台执行失败
Traceback (most recent call last):
  File "D:\sktest\common\testsuit.py", line 34, in run
    tc.run()
  File "D:\sktest\common\testcase.py", line 16, in run
    logger.info("Run The Step: %s|%s|%s" % (int(step['step']), step['operation'], step['element']))
ValueError: invalid literal for int() with base 10: '1.0'
2020-08-25 13:17:15,680 [INFO]: #  **** 解析用例成功 ****
2020-08-25 13:17:15,680 [INFO]: #  -------- Run The TestCase：test-2 打开搜狗
2020-08-25 13:17:15,694 [ERROR]: #  用例test-2:打开搜狗执行失败
Traceback (most recent call last):
  File "D:\sktest\common\testsuit.py", line 34, in run
    tc.run()
  File "D:\sktest\common\testcase.py", line 16, in run
    logger.info("Run The Step: %s|%s|%s" % (int(step['step']), step['operation'], step['element']))
ValueError: invalid literal for int() with base 10: '1.0'
2020-08-25 13:18:32,440 [INFO]: #  **** 从Excel导入用例套件成功 ****
2020-08-25 13:18:32,440 [INFO]: #  **** 解析用例成功 ****
2020-08-25 13:18:32,440 [INFO]: #  -------- Run The TestCase：test-1 验证码登录运营中台
2020-08-25 13:18:32,440 [ERROR]: #  用例test-1:验证码登录运营中台执行失败
Traceback (most recent call last):
  File "D:\sktest\common\testsuit.py", line 34, in run
    tc.run()
  File "D:\sktest\common\testcase.py", line 18, in run
    logger.info("Run The Step: %s|%s|%s" % (int(step['step']), step['operation'], step['element']))
ValueError: invalid literal for int() with base 10: '1.0'
2020-08-25 13:18:32,440 [INFO]: #  **** 解析用例成功 ****
2020-08-25 13:18:32,440 [INFO]: #  -------- Run The TestCase：test-2 打开搜狗
2020-08-25 13:18:32,440 [ERROR]: #  用例test-2:打开搜狗执行失败
Traceback (most recent call last):
  File "D:\sktest\common\testsuit.py", line 34, in run
    tc.run()
  File "D:\sktest\common\testcase.py", line 18, in run
    logger.info("Run The Step: %s|%s|%s" % (int(step['step']), step['operation'], step['element']))
ValueError: invalid literal for int() with base 10: '1.0'
2020-08-25 13:23:12,482 [INFO]: #  **** 从Excel导入用例套件成功 ****
2020-08-25 13:23:12,482 [INFO]: #  **** 解析用例成功 ****
2020-08-25 13:23:12,482 [INFO]: #  -------- Run The TestCase：test-1 验证码登录运营中台
2020-08-25 13:23:12,482 [INFO]: #  Run The Step: 1.0|OPEN|百度搜索链接2
2020-08-25 13:23:12,497 [ERROR]: #  用例test-1:验证码登录运营中台执行失败
Traceback (most recent call last):
  File "D:\sktest\common\testcase.py", line 21, in run
    getattr(Action, step['operation'].lower())(step)
  File "D:\sktest\common\acction.py", line 19, in open
    g.driver.get(value)
  File "D:\sktest\venv\lib\site-packages\selenium\webdriver\remote\webdriver.py", line 333, in get
    self.execute(Command.GET, {'url': url})
  File "D:\sktest\venv\lib\site-packages\selenium\webdriver\remote\webdriver.py", line 321, in execute
    self.error_handler.check_response(response)
  File "D:\sktest\venv\lib\site-packages\selenium\webdriver\remote\errorhandler.py", line 242, in check_response
    raise exception_class(message, screen, stacktrace)
selenium.common.exceptions.InvalidArgumentException: Message: invalid argument
  (Session info: chrome=77.0.3865.90)


During handling of the above exception, another exception occurred:

Traceback (most recent call last):
  File "D:\sktest\common\testsuit.py", line 34, in run
    tc.run()
  File "D:\sktest\common\testcase.py", line 25, in run
    logger.info("Run The Step: %s|%s|%s Fail" % (int(step['step']), step['operation'], step['element']))
ValueError: invalid literal for int() with base 10: '1.0'
2020-08-25 13:23:12,547 [INFO]: #  **** 解析用例成功 ****
2020-08-25 13:23:12,547 [INFO]: #  -------- Run The TestCase：test-2 打开搜狗
2020-08-25 13:23:12,547 [INFO]: #  Run The Step: 1.0|OPEN|搜狗链接
2020-08-25 13:23:13,573 [ERROR]: #  用例test-2:打开搜狗执行失败
Traceback (most recent call last):
  File "D:\sktest\common\testcase.py", line 22, in run
    logger.info("Run The Step: %s|%s|%s Success" % (int(step['step']), step['operation'], step['element']))
ValueError: invalid literal for int() with base 10: '1.0'

During handling of the above exception, another exception occurred:

Traceback (most recent call last):
  File "D:\sktest\common\testsuit.py", line 34, in run
    tc.run()
  File "D:\sktest\common\testcase.py", line 25, in run
    logger.info("Run The Step: %s|%s|%s Fail" % (int(step['step']), step['operation'], step['element']))
ValueError: invalid literal for int() with base 10: '1.0'
2020-08-25 13:24:02,054 [INFO]: #  **** 从Excel导入用例套件成功 ****
2020-08-25 13:24:02,058 [INFO]: #  **** 解析用例成功 ****
2020-08-25 13:24:02,058 [INFO]: #  -------- Run The TestCase：test-1 验证码登录运营中台
2020-08-25 13:24:02,058 [INFO]: #  Run The Step: 1.0|OPEN|百度搜索链接2
2020-08-25 13:24:02,068 [ERROR]: #  用例test-1:验证码登录运营中台执行失败
Traceback (most recent call last):
  File "D:\sktest\common\testcase.py", line 21, in run
    getattr(Action, step['operation'].lower())(step)
  File "D:\sktest\common\acction.py", line 19, in open
    g.driver.get(value)
  File "D:\sktest\venv\lib\site-packages\selenium\webdriver\remote\webdriver.py", line 333, in get
    self.execute(Command.GET, {'url': url})
  File "D:\sktest\venv\lib\site-packages\selenium\webdriver\remote\webdriver.py", line 321, in execute
    self.error_handler.check_response(response)
  File "D:\sktest\venv\lib\site-packages\selenium\webdriver\remote\errorhandler.py", line 242, in check_response
    raise exception_class(message, screen, stacktrace)
selenium.common.exceptions.InvalidArgumentException: Message: invalid argument
  (Session info: chrome=77.0.3865.90)


During handling of the above exception, another exception occurred:

Traceback (most recent call last):
  File "D:\sktest\common\testsuit.py", line 34, in run
    tc.run()
  File "D:\sktest\common\testcase.py", line 25, in run
    logger.info("Run The Step: %s|%s|%s Fail" % (int(step['step']), step['operation'], step['element']))
ValueError: invalid literal for int() with base 10: '1.0'
2020-08-25 13:24:02,072 [INFO]: #  **** 解析用例成功 ****
2020-08-25 13:24:02,072 [INFO]: #  -------- Run The TestCase：test-2 打开搜狗
2020-08-25 13:24:02,072 [INFO]: #  Run The Step: 1.0|OPEN|搜狗链接
2020-08-25 13:24:03,134 [INFO]: #  Run The Step: 1.0|OPEN|搜狗-搜狗链接 Success
2020-08-25 13:24:04,137 [INFO]: #  ****  用例执行成功  ****
2020-08-25 13:28:37,296 [INFO]: #  **** 从Excel导入用例套件成功 ****
2020-08-25 13:28:37,296 [INFO]: #  **** 解析用例成功 ****
2020-08-25 13:28:37,297 [INFO]: #  -------- Run The TestCase：test-1 验证码登录运营中台
2020-08-25 13:28:37,297 [INFO]: #  Run The Step: 1|OPEN|百度搜索链接2
2020-08-25 13:28:37,306 [INFO]: #  Run The Step: 1|OPEN|百度-百度搜索链接2 Fail
2020-08-25 13:28:37,306 [INFO]: #  Run The Step: 2|INPUT|百度搜索框
2020-08-25 13:29:00,397 [INFO]: #  Run The Step: 2|INPUT|百度-百度搜索框 Fail
2020-08-25 13:29:00,397 [INFO]: #  Run The Step: 3|CLICK|百度搜索按钮
2020-08-25 13:29:24,400 [INFO]: #  Run The Step: 3|CLICK|百度-百度搜索按钮 Fail
2020-08-25 13:29:24,912 [INFO]: #  ****  用例执行成功  ****
2020-08-25 13:29:24,912 [INFO]: #  **** 解析用例成功 ****
2020-08-25 13:29:24,912 [INFO]: #  -------- Run The TestCase：test-2 打开搜狗
2020-08-25 13:29:24,912 [INFO]: #  Run The Step: 1|OPEN|搜狗链接
2020-08-25 13:29:26,043 [INFO]: #  Run The Step: 1.0|OPEN|搜狗-搜狗链接 Success
2020-08-25 13:29:27,047 [INFO]: #  ****  用例执行成功  ****
2020-08-25 13:32:52,101 [INFO]: #  **** 从Excel导入用例套件成功 ****
2020-08-25 13:32:52,101 [INFO]: #  **** 解析用例成功 ****
2020-08-25 13:32:52,102 [INFO]: #  -------- Run The TestCase：test-1 验证码登录运营中台
2020-08-25 13:32:52,102 [INFO]: #  Run The Step: 1|OPEN|百度搜索链接2
2020-08-25 13:32:52,113 [INFO]: #  Run The Step: 1|OPEN|百度-百度搜索链接2 Fail
2020-08-25 13:32:52,113 [INFO]: #  Run The Step: 2|INPUT|百度搜索框
2020-08-25 13:33:15,676 [INFO]: #  Run The Step: 2|INPUT|百度-百度搜索框 Fail
2020-08-25 13:33:15,676 [INFO]: #  Run The Step: 3|CLICK|百度搜索按钮
2020-08-25 13:33:38,741 [INFO]: #  Run The Step: 3|CLICK|百度-百度搜索按钮 Fail
2020-08-25 13:33:39,257 [INFO]: #  ****  用例执行完成  ****
2020-08-25 13:33:39,257 [INFO]: #  **** 解析用例成功 ****
2020-08-25 13:33:39,258 [INFO]: #  -------- Run The TestCase：test-2 打开搜狗
2020-08-25 13:33:39,258 [INFO]: #  Run The Step: 1|OPEN|搜狗链接
2020-08-25 13:33:40,357 [INFO]: #  Run The Step: 1.0|OPEN|搜狗-搜狗链接 Success
2020-08-25 13:33:41,366 [INFO]: #  ****  用例执行完成  ****
2020-08-25 13:38:55,590 [INFO]: #  **** 从Excel导入用例套件成功 ****
2020-08-25 13:38:55,590 [INFO]: #  **** 解析用例成功 ****
2020-08-25 13:38:55,590 [INFO]: #  -------- Run The TestCase：test-1 验证码登录运营中台
2020-08-25 13:38:55,590 [INFO]: #  Run The Step: 1|OPEN|百度搜索链接2
2020-08-25 13:38:55,605 [INFO]: #  Run The Step: 1|OPEN|百度-百度搜索链接2 Fail
2020-08-25 13:38:55,605 [INFO]: #  Run The Step: 2|INPUT|百度搜索框
2020-08-25 13:39:06,123 [ERROR]: #  元素：百度-百度搜索框第一次定位失败，等待三秒重试！！！
Traceback (most recent call last):
  File "D:\sktest\common\locator.py", line 25, in locating_element
    element_location = wait.until(EC.presence_of_element_located((getattr(By, el_['by'].upper()), value)))
  File "D:\sktest\venv\lib\site-packages\selenium\webdriver\support\wait.py", line 80, in until
    raise TimeoutException(message, screen, stacktrace)
selenium.common.exceptions.TimeoutException: Message: 

2020-08-25 13:39:19,219 [ERROR]: #  元素：百度-百度搜索框定位超时
Traceback (most recent call last):
  File "D:\sktest\common\locator.py", line 25, in locating_element
    element_location = wait.until(EC.presence_of_element_located((getattr(By, el_['by'].upper()), value)))
  File "D:\sktest\venv\lib\site-packages\selenium\webdriver\support\wait.py", line 80, in until
    raise TimeoutException(message, screen, stacktrace)
selenium.common.exceptions.TimeoutException: Message: 


During handling of the above exception, another exception occurred:

Traceback (most recent call last):
  File "D:\sktest\common\locator.py", line 30, in locating_element
    element_location = wait.until(EC.presence_of_element_located((getattr(By, el_['by'].upper()), value)))
  File "D:\sktest\venv\lib\site-packages\selenium\webdriver\support\wait.py", line 80, in until
    raise TimeoutException(message, screen, stacktrace)
selenium.common.exceptions.TimeoutException: Message: 

2020-08-25 13:39:19,222 [INFO]: #  Run The Step: 2|INPUT|百度-百度搜索框 Fail
2020-08-25 13:39:19,222 [INFO]: #  Run The Step: 3|CLICK|百度搜索按钮
2020-08-25 13:39:29,301 [ERROR]: #  元素：百度-百度搜索按钮第一次定位失败，等待三秒重试！！！
Traceback (most recent call last):
  File "D:\sktest\common\locator.py", line 25, in locating_element
    element_location = wait.until(EC.presence_of_element_located((getattr(By, el_['by'].upper()), value)))
  File "D:\sktest\venv\lib\site-packages\selenium\webdriver\support\wait.py", line 80, in until
    raise TimeoutException(message, screen, stacktrace)
selenium.common.exceptions.TimeoutException: Message: 

2020-08-25 13:39:42,312 [ERROR]: #  元素：百度-百度搜索按钮定位超时
Traceback (most recent call last):
  File "D:\sktest\common\locator.py", line 25, in locating_element
    element_location = wait.until(EC.presence_of_element_located((getattr(By, el_['by'].upper()), value)))
  File "D:\sktest\venv\lib\site-packages\selenium\webdriver\support\wait.py", line 80, in until
    raise TimeoutException(message, screen, stacktrace)
selenium.common.exceptions.TimeoutException: Message: 


During handling of the above exception, another exception occurred:

Traceback (most recent call last):
  File "D:\sktest\common\locator.py", line 30, in locating_element
    element_location = wait.until(EC.presence_of_element_located((getattr(By, el_['by'].upper()), value)))
  File "D:\sktest\venv\lib\site-packages\selenium\webdriver\support\wait.py", line 80, in until
    raise TimeoutException(message, screen, stacktrace)
selenium.common.exceptions.TimeoutException: Message: 

2020-08-25 13:39:42,313 [INFO]: #  Run The Step: 3|CLICK|百度-百度搜索按钮 Fail
2020-08-25 13:39:42,829 [INFO]: #  ****  用例执行完成  ****
2020-08-25 13:39:42,829 [INFO]: #  **** 解析用例成功 ****
2020-08-25 13:39:42,829 [INFO]: #  -------- Run The TestCase：test-2 打开搜狗
2020-08-25 13:39:42,830 [INFO]: #  Run The Step: 1|OPEN|搜狗链接
2020-08-25 13:39:44,996 [INFO]: #  Run The Step: 1|OPEN|搜狗-搜狗链接 Success
2020-08-25 13:39:45,802 [INFO]: #  ****  用例执行完成  ****
2020-08-25 13:41:56,657 [INFO]: #  **** 从Excel导入用例套件成功 ****
2020-08-25 13:41:56,657 [INFO]: #  **** 解析用例成功 ****
2020-08-25 13:41:56,657 [INFO]: #  -------- Run The TestCase：test-1 验证码登录运营中台
2020-08-25 13:41:56,657 [INFO]: #  Run The Step: 1|OPEN|百度搜索链接
2020-08-25 13:41:57,861 [INFO]: #  Run The Step: 1|OPEN|百度-百度搜索链接 Success
2020-08-25 13:41:58,167 [INFO]: #  Run The Step: 2|INPUT|百度搜索框
2020-08-25 13:41:58,827 [INFO]: #  Run The Step: 2|INPUT|百度-百度搜索框 Success
2020-08-25 13:41:59,144 [INFO]: #  Run The Step: 3|CLICK|百度搜索按钮
2020-08-25 13:41:59,790 [INFO]: #  Run The Step: 3|CLICK|百度-百度搜索按钮 Success
2020-08-25 13:42:00,606 [INFO]: #  ****  用例执行完成  ****
2020-08-25 13:42:00,607 [INFO]: #  **** 解析用例成功 ****
2020-08-25 13:42:00,607 [INFO]: #  -------- Run The TestCase：test-2 打开搜狗
2020-08-25 13:42:00,607 [INFO]: #  Run The Step: 1|OPEN|搜狗链接
2020-08-25 13:42:01,794 [INFO]: #  Run The Step: 1|OPEN|搜狗-搜狗链接 Success
2020-08-25 13:42:02,598 [INFO]: #  ****  用例执行完成  ****
2020-08-25 14:20:27,560 [INFO]: #  ####  未指定driver 默认启动Chrome，请确保driver配置了系统环境或者在python安装目录下！！！
2020-08-25 14:20:32,861 [INFO]: #  **** 从Excel导入用例套件成功 ****
2020-08-25 14:20:32,861 [INFO]: #  **** 解析用例成功 ****
2020-08-25 14:20:32,863 [INFO]: #  -------- Run The TestCase：test-1 验证码登录运营中台
2020-08-25 14:20:32,863 [INFO]: #  Run The Step: 1|OPEN|百度搜索链接
2020-08-25 14:20:34,014 [INFO]: #  Run The Step: 1|OPEN|百度-百度搜索链接 Success
2020-08-25 14:20:34,320 [INFO]: #  Run The Step: 2|INPUT|百度搜索框
2020-08-25 14:20:35,021 [INFO]: #  Run The Step: 2|INPUT|百度-百度搜索框 Success
2020-08-25 14:20:35,323 [INFO]: #  Run The Step: 3|CLICK|百度搜索按钮
2020-08-25 14:20:35,910 [INFO]: #  Run The Step: 3|CLICK|百度-百度搜索按钮 Success
2020-08-25 14:20:36,719 [INFO]: #  ****  用例执行完成  ****
2020-08-25 14:20:36,719 [INFO]: #  **** 解析用例成功 ****
2020-08-25 14:20:36,719 [INFO]: #  -------- Run The TestCase：test-2 打开搜狗
2020-08-25 14:20:36,719 [INFO]: #  Run The Step: 1|OPEN|搜狗链接
2020-08-25 14:20:37,922 [INFO]: #  Run The Step: 1|OPEN|搜狗-搜狗链接 Success
2020-08-25 14:20:38,726 [INFO]: #  ****  用例执行完成  ****
2020-08-25 14:23:59,923 [ERROR]: #  #### driver 初始化失败！@或许你需要检查executable_path配置！！！
Traceback (most recent call last):
  File "D:\sktest\venv\lib\site-packages\selenium\webdriver\common\service.py", line 76, in start
    stdin=PIPE)
  File "D:\Program Files (x86)\python37\lib\subprocess.py", line 756, in __init__
    restore_signals, start_new_session)
  File "D:\Program Files (x86)\python37\lib\subprocess.py", line 1155, in _execute_child
    startupinfo)
FileNotFoundError: [WinError 2] 系统找不到指定的文件。

During handling of the above exception, another exception occurred:

Traceback (most recent call last):
  File "D:\sktest\common\globals.py", line 26, in init
    self.driver = webdriver.Chrome(executable_path=self.executable_path)
  File "D:\sktest\venv\lib\site-packages\selenium\webdriver\chrome\webdriver.py", line 73, in __init__
    self.service.start()
  File "D:\sktest\venv\lib\site-packages\selenium\webdriver\common\service.py", line 83, in start
    os.path.basename(self.path), self.start_error_message)
selenium.common.exceptions.WebDriverException: Message: '2' executable needs to be in PATH. Please see https://sites.google.com/a/chromium.org/chromedriver/home

2020-08-25 14:24:00,005 [INFO]: #  **** 从Excel导入用例套件成功 ****
2020-08-25 14:24:00,005 [INFO]: #  **** 解析用例成功 ****
2020-08-25 14:24:00,005 [INFO]: #  -------- Run The TestCase：test-1 验证码登录运营中台
2020-08-25 14:24:00,005 [INFO]: #  Run The Step: 1|OPEN|百度搜索链接
2020-08-25 14:24:00,005 [INFO]: #  Run The Step: 1|OPEN|百度-百度搜索链接 Fail
2020-08-25 14:24:00,005 [INFO]: #  Run The Step: 2|INPUT|百度搜索框
2020-08-25 14:24:00,005 [ERROR]: #  元素：百度-百度搜索框第一次定位失败，等待三秒重试！！！
Traceback (most recent call last):
  File "D:\sktest\common\locator.py", line 25, in locating_element
    element_location = wait.until(EC.presence_of_element_located((getattr(By, el_['by'].upper()), value)))
  File "D:\sktest\venv\lib\site-packages\selenium\webdriver\support\wait.py", line 71, in until
    value = method(self._driver)
  File "D:\sktest\venv\lib\site-packages\selenium\webdriver\support\expected_conditions.py", line 64, in __call__
    return _find_element(driver, self.locator)
  File "D:\sktest\venv\lib\site-packages\selenium\webdriver\support\expected_conditions.py", line 411, in _find_element
    return driver.find_element(*by)
AttributeError: 'str' object has no attribute 'find_element'
2020-08-25 14:24:03,028 [ERROR]: #  元素：百度-百度搜索框定位超时
Traceback (most recent call last):
  File "D:\sktest\common\locator.py", line 25, in locating_element
    element_location = wait.until(EC.presence_of_element_located((getattr(By, el_['by'].upper()), value)))
  File "D:\sktest\venv\lib\site-packages\selenium\webdriver\support\wait.py", line 71, in until
    value = method(self._driver)
  File "D:\sktest\venv\lib\site-packages\selenium\webdriver\support\expected_conditions.py", line 64, in __call__
    return _find_element(driver, self.locator)
  File "D:\sktest\venv\lib\site-packages\selenium\webdriver\support\expected_conditions.py", line 411, in _find_element
    return driver.find_element(*by)
AttributeError: 'str' object has no attribute 'find_element'

During handling of the above exception, another exception occurred:

Traceback (most recent call last):
  File "D:\sktest\common\locator.py", line 30, in locating_element
    element_location = wait.until(EC.presence_of_element_located((getattr(By, el_['by'].upper()), value)))
  File "D:\sktest\venv\lib\site-packages\selenium\webdriver\support\wait.py", line 71, in until
    value = method(self._driver)
  File "D:\sktest\venv\lib\site-packages\selenium\webdriver\support\expected_conditions.py", line 64, in __call__
    return _find_element(driver, self.locator)
  File "D:\sktest\venv\lib\site-packages\selenium\webdriver\support\expected_conditions.py", line 411, in _find_element
    return driver.find_element(*by)
AttributeError: 'str' object has no attribute 'find_element'
2020-08-25 14:24:03,031 [INFO]: #  Run The Step: 2|INPUT|百度-百度搜索框 Fail
2020-08-25 14:24:03,031 [INFO]: #  Run The Step: 3|CLICK|百度搜索按钮
2020-08-25 14:24:03,032 [ERROR]: #  元素：百度-百度搜索按钮第一次定位失败，等待三秒重试！！！
Traceback (most recent call last):
  File "D:\sktest\common\locator.py", line 25, in locating_element
    element_location = wait.until(EC.presence_of_element_located((getattr(By, el_['by'].upper()), value)))
  File "D:\sktest\venv\lib\site-packages\selenium\webdriver\support\wait.py", line 71, in until
    value = method(self._driver)
  File "D:\sktest\venv\lib\site-packages\selenium\webdriver\support\expected_conditions.py", line 64, in __call__
    return _find_element(driver, self.locator)
  File "D:\sktest\venv\lib\site-packages\selenium\webdriver\support\expected_conditions.py", line 411, in _find_element
    return driver.find_element(*by)
AttributeError: 'str' object has no attribute 'find_element'
2020-08-25 14:24:06,036 [ERROR]: #  元素：百度-百度搜索按钮定位超时
Traceback (most recent call last):
  File "D:\sktest\common\locator.py", line 25, in locating_element
    element_location = wait.until(EC.presence_of_element_located((getattr(By, el_['by'].upper()), value)))
  File "D:\sktest\venv\lib\site-packages\selenium\webdriver\support\wait.py", line 71, in until
    value = method(self._driver)
  File "D:\sktest\venv\lib\site-packages\selenium\webdriver\support\expected_conditions.py", line 64, in __call__
    return _find_element(driver, self.locator)
  File "D:\sktest\venv\lib\site-packages\selenium\webdriver\support\expected_conditions.py", line 411, in _find_element
    return driver.find_element(*by)
AttributeError: 'str' object has no attribute 'find_element'

During handling of the above exception, another exception occurred:

Traceback (most recent call last):
  File "D:\sktest\common\locator.py", line 30, in locating_element
    element_location = wait.until(EC.presence_of_element_located((getattr(By, el_['by'].upper()), value)))
  File "D:\sktest\venv\lib\site-packages\selenium\webdriver\support\wait.py", line 71, in until
    value = method(self._driver)
  File "D:\sktest\venv\lib\site-packages\selenium\webdriver\support\expected_conditions.py", line 64, in __call__
    return _find_element(driver, self.locator)
  File "D:\sktest\venv\lib\site-packages\selenium\webdriver\support\expected_conditions.py", line 411, in _find_element
    return driver.find_element(*by)
AttributeError: 'str' object has no attribute 'find_element'
2020-08-25 14:24:06,039 [INFO]: #  Run The Step: 3|CLICK|百度-百度搜索按钮 Fail
2020-08-25 14:24:06,552 [INFO]: #  ****  用例执行完成  ****
2020-08-25 14:24:06,553 [INFO]: #  **** 解析用例成功 ****
2020-08-25 14:24:06,553 [INFO]: #  -------- Run The TestCase：test-2 打开搜狗
2020-08-25 14:24:06,553 [INFO]: #  Run The Step: 1|OPEN|搜狗链接
2020-08-25 14:24:06,553 [INFO]: #  Run The Step: 1|OPEN|搜狗-搜狗链接 Fail
2020-08-25 14:24:07,057 [INFO]: #  ****  用例执行完成  ****
2020-08-25 14:24:48,626 [ERROR]: #  #### driver 初始化失败！@或许你需要检查executable_path配置！！！
Traceback (most recent call last):
  File "D:\sktest\venv\lib\site-packages\selenium\webdriver\common\service.py", line 76, in start
    stdin=PIPE)
  File "D:\Program Files (x86)\python37\lib\subprocess.py", line 756, in __init__
    restore_signals, start_new_session)
  File "D:\Program Files (x86)\python37\lib\subprocess.py", line 1155, in _execute_child
    startupinfo)
FileNotFoundError: [WinError 2] 系统找不到指定的文件。

During handling of the above exception, another exception occurred:

Traceback (most recent call last):
  File "D:\sktest\common\globals.py", line 26, in init
    self.driver = webdriver.Chrome(executable_path=self.executable_path)
  File "D:\sktest\venv\lib\site-packages\selenium\webdriver\chrome\webdriver.py", line 73, in __init__
    self.service.start()
  File "D:\sktest\venv\lib\site-packages\selenium\webdriver\common\service.py", line 83, in start
    os.path.basename(self.path), self.start_error_message)
selenium.common.exceptions.WebDriverException: Message: '2' executable needs to be in PATH. Please see https://sites.google.com/a/chromium.org/chromedriver/home

2020-08-25 14:24:48,642 [INFO]: #  **** 从Excel导入用例套件成功 ****
2020-08-25 14:24:48,643 [INFO]: #  **** 解析用例成功 ****
2020-08-25 14:24:48,643 [INFO]: #  -------- Run The TestCase：test-1 验证码登录运营中台
2020-08-25 14:24:48,643 [INFO]: #  Run The Step: 1|OPEN|百度搜索链接
2020-08-25 14:24:48,643 [INFO]: #  Run The Step: 1|OPEN|百度-百度搜索链接 Fail
2020-08-25 14:24:48,643 [INFO]: #  Run The Step: 2|INPUT|百度搜索框
2020-08-25 14:24:48,643 [ERROR]: #  元素：百度-百度搜索框第一次定位失败，等待三秒重试！！！
Traceback (most recent call last):
  File "D:\sktest\common\locator.py", line 25, in locating_element
    element_location = wait.until(EC.presence_of_element_located((getattr(By, el_['by'].upper()), value)))
  File "D:\sktest\venv\lib\site-packages\selenium\webdriver\support\wait.py", line 71, in until
    value = method(self._driver)
  File "D:\sktest\venv\lib\site-packages\selenium\webdriver\support\expected_conditions.py", line 64, in __call__
    return _find_element(driver, self.locator)
  File "D:\sktest\venv\lib\site-packages\selenium\webdriver\support\expected_conditions.py", line 411, in _find_element
    return driver.find_element(*by)
AttributeError: 'str' object has no attribute 'find_element'
2020-08-25 14:24:51,646 [ERROR]: #  元素：百度-百度搜索框定位超时
Traceback (most recent call last):
  File "D:\sktest\common\locator.py", line 25, in locating_element
    element_location = wait.until(EC.presence_of_element_located((getattr(By, el_['by'].upper()), value)))
  File "D:\sktest\venv\lib\site-packages\selenium\webdriver\support\wait.py", line 71, in until
    value = method(self._driver)
  File "D:\sktest\venv\lib\site-packages\selenium\webdriver\support\expected_conditions.py", line 64, in __call__
    return _find_element(driver, self.locator)
  File "D:\sktest\venv\lib\site-packages\selenium\webdriver\support\expected_conditions.py", line 411, in _find_element
    return driver.find_element(*by)
AttributeError: 'str' object has no attribute 'find_element'

During handling of the above exception, another exception occurred:

Traceback (most recent call last):
  File "D:\sktest\common\locator.py", line 30, in locating_element
    element_location = wait.until(EC.presence_of_element_located((getattr(By, el_['by'].upper()), value)))
  File "D:\sktest\venv\lib\site-packages\selenium\webdriver\support\wait.py", line 71, in until
    value = method(self._driver)
  File "D:\sktest\venv\lib\site-packages\selenium\webdriver\support\expected_conditions.py", line 64, in __call__
    return _find_element(driver, self.locator)
  File "D:\sktest\venv\lib\site-packages\selenium\webdriver\support\expected_conditions.py", line 411, in _find_element
    return driver.find_element(*by)
AttributeError: 'str' object has no attribute 'find_element'
2020-08-25 14:24:51,649 [INFO]: #  Run The Step: 2|INPUT|百度-百度搜索框 Fail
2020-08-25 14:24:51,649 [INFO]: #  Run The Step: 3|CLICK|百度搜索按钮
2020-08-25 14:24:51,650 [ERROR]: #  元素：百度-百度搜索按钮第一次定位失败，等待三秒重试！！！
Traceback (most recent call last):
  File "D:\sktest\common\locator.py", line 25, in locating_element
    element_location = wait.until(EC.presence_of_element_located((getattr(By, el_['by'].upper()), value)))
  File "D:\sktest\venv\lib\site-packages\selenium\webdriver\support\wait.py", line 71, in until
    value = method(self._driver)
  File "D:\sktest\venv\lib\site-packages\selenium\webdriver\support\expected_conditions.py", line 64, in __call__
    return _find_element(driver, self.locator)
  File "D:\sktest\venv\lib\site-packages\selenium\webdriver\support\expected_conditions.py", line 411, in _find_element
    return driver.find_element(*by)
AttributeError: 'str' object has no attribute 'find_element'
2020-08-25 14:24:54,680 [ERROR]: #  元素：百度-百度搜索按钮定位超时
Traceback (most recent call last):
  File "D:\sktest\common\locator.py", line 25, in locating_element
    element_location = wait.until(EC.presence_of_element_located((getattr(By, el_['by'].upper()), value)))
  File "D:\sktest\venv\lib\site-packages\selenium\webdriver\support\wait.py", line 71, in until
    value = method(self._driver)
  File "D:\sktest\venv\lib\site-packages\selenium\webdriver\support\expected_conditions.py", line 64, in __call__
    return _find_element(driver, self.locator)
  File "D:\sktest\venv\lib\site-packages\selenium\webdriver\support\expected_conditions.py", line 411, in _find_element
    return driver.find_element(*by)
AttributeError: 'str' object has no attribute 'find_element'

During handling of the above exception, another exception occurred:

Traceback (most recent call last):
  File "D:\sktest\common\locator.py", line 30, in locating_element
    element_location = wait.until(EC.presence_of_element_located((getattr(By, el_['by'].upper()), value)))
  File "D:\sktest\venv\lib\site-packages\selenium\webdriver\support\wait.py", line 71, in until
    value = method(self._driver)
  File "D:\sktest\venv\lib\site-packages\selenium\webdriver\support\expected_conditions.py", line 64, in __call__
    return _find_element(driver, self.locator)
  File "D:\sktest\venv\lib\site-packages\selenium\webdriver\support\expected_conditions.py", line 411, in _find_element
    return driver.find_element(*by)
AttributeError: 'str' object has no attribute 'find_element'
2020-08-25 14:24:54,681 [INFO]: #  Run The Step: 3|CLICK|百度-百度搜索按钮 Fail
2020-08-25 14:24:55,197 [INFO]: #  ****  用例执行完成  ****
2020-08-25 14:24:55,197 [INFO]: #  **** 解析用例成功 ****
2020-08-25 14:24:55,198 [INFO]: #  -------- Run The TestCase：test-2 打开搜狗
2020-08-25 14:24:55,198 [INFO]: #  Run The Step: 1|OPEN|搜狗链接
2020-08-25 14:24:55,198 [INFO]: #  Run The Step: 1|OPEN|搜狗-搜狗链接 Fail
2020-08-25 14:24:55,711 [INFO]: #  ****  用例执行完成  ****
2020-08-25 14:26:22,562 [ERROR]: #  #### driver 初始化失败！@或许你需要检查executable_path配置！！！
Traceback (most recent call last):
  File "D:\sktest\venv\lib\site-packages\selenium\webdriver\common\service.py", line 76, in start
    stdin=PIPE)
  File "D:\Program Files (x86)\python37\lib\subprocess.py", line 756, in __init__
    restore_signals, start_new_session)
  File "D:\Program Files (x86)\python37\lib\subprocess.py", line 1155, in _execute_child
    startupinfo)
FileNotFoundError: [WinError 2] 系统找不到指定的文件。

During handling of the above exception, another exception occurred:

Traceback (most recent call last):
  File "D:\sktest\common\globals.py", line 26, in init
    self.driver = webdriver.Chrome(executable_path=self.executable_path)
  File "D:\sktest\venv\lib\site-packages\selenium\webdriver\chrome\webdriver.py", line 73, in __init__
    self.service.start()
  File "D:\sktest\venv\lib\site-packages\selenium\webdriver\common\service.py", line 83, in start
    os.path.basename(self.path), self.start_error_message)
selenium.common.exceptions.WebDriverException: Message: '2' executable needs to be in PATH. Please see https://sites.google.com/a/chromium.org/chromedriver/home

2020-08-25 14:28:49,546 [INFO]: #  **** 从Excel导入用例套件成功 ****
2020-08-25 14:28:49,546 [INFO]: #  **** 解析用例成功 ****
2020-08-25 14:28:49,546 [INFO]: #  -------- Run The TestCase：test-1 验证码登录运营中台
2020-08-25 14:28:49,546 [INFO]: #  Run The Step: 1|OPEN|百度搜索链接
2020-08-25 14:28:50,949 [INFO]: #  Run The Step: 1|OPEN|百度-百度搜索链接 Success
2020-08-25 14:28:51,253 [INFO]: #  Run The Step: 2|INPUT|百度搜索框
2020-08-25 14:28:51,883 [INFO]: #  Run The Step: 2|INPUT|百度-百度搜索框 Success
2020-08-25 14:28:52,196 [INFO]: #  Run The Step: 3|CLICK|百度搜索按钮
2020-08-25 14:28:52,787 [INFO]: #  Run The Step: 3|CLICK|百度-百度搜索按钮 Success
2020-08-25 14:28:53,593 [INFO]: #  ****  用例执行完成  ****
2020-08-25 14:28:53,593 [INFO]: #  **** 解析用例成功 ****
2020-08-25 14:28:53,593 [INFO]: #  -------- Run The TestCase：test-2 打开搜狗
2020-08-25 14:28:53,593 [INFO]: #  Run The Step: 1|OPEN|搜狗链接
2020-08-25 14:28:54,896 [INFO]: #  Run The Step: 1|OPEN|搜狗-搜狗链接 Success
2020-08-25 14:28:55,702 [INFO]: #  ****  用例执行完成  ****
2020-08-25 14:29:09,347 [INFO]: #  **** 从Excel导入用例套件成功 ****
2020-08-25 14:29:09,347 [INFO]: #  **** 解析用例成功 ****
2020-08-25 14:29:09,347 [INFO]: #  -------- Run The TestCase：test-1 验证码登录运营中台
2020-08-25 14:29:09,347 [INFO]: #  Run The Step: 1|OPEN|百度搜索链接
2020-08-25 14:29:10,797 [INFO]: #  Run The Step: 1|OPEN|百度-百度搜索链接 Success
2020-08-25 14:29:11,098 [INFO]: #  Run The Step: 2|INPUT|百度搜索框
2020-08-25 14:29:11,724 [INFO]: #  Run The Step: 2|INPUT|百度-百度搜索框 Success
2020-08-25 14:29:12,027 [INFO]: #  Run The Step: 3|CLICK|百度搜索按钮
2020-08-25 14:29:12,698 [INFO]: #  Run The Step: 3|CLICK|百度-百度搜索按钮 Success
2020-08-25 14:29:13,504 [INFO]: #  ****  用例执行完成  ****
2020-08-25 14:29:13,504 [INFO]: #  **** 解析用例成功 ****
2020-08-25 14:29:13,504 [INFO]: #  -------- Run The TestCase：test-2 打开搜狗
2020-08-25 14:29:13,504 [INFO]: #  Run The Step: 1|OPEN|搜狗链接
2020-08-25 14:29:14,775 [INFO]: #  Run The Step: 1|OPEN|搜狗-搜狗链接 Success
2020-08-25 14:29:15,583 [INFO]: #  ****  用例执行完成  ****
2020-08-25 14:30:25,718 [INFO]: #  **** 从Excel导入用例套件成功 ****
2020-08-25 14:30:25,718 [INFO]: #  **** 解析用例成功 ****
2020-08-25 14:30:25,718 [INFO]: #  -------- Run The TestCase：test-1 验证码登录运营中台
2020-08-25 14:30:25,718 [INFO]: #  Run The Step: 1|OPEN|百度搜索链接
2020-08-25 14:30:25,718 [INFO]: #  Run The Step: 1|OPEN|百度-百度搜索链接 Fail
2020-08-25 14:30:25,718 [INFO]: #  Run The Step: 2|INPUT|百度搜索框
2020-08-25 14:30:25,718 [ERROR]: #  元素：百度-百度搜索框第一次定位失败，等待三秒重试！！！
Traceback (most recent call last):
  File "D:\sktest\common\locator.py", line 25, in locating_element
    element_location = wait.until(EC.presence_of_element_located((getattr(By, el_['by'].upper()), value)))
  File "D:\sktest\venv\lib\site-packages\selenium\webdriver\support\wait.py", line 71, in until
    value = method(self._driver)
  File "D:\sktest\venv\lib\site-packages\selenium\webdriver\support\expected_conditions.py", line 64, in __call__
    return _find_element(driver, self.locator)
  File "D:\sktest\venv\lib\site-packages\selenium\webdriver\support\expected_conditions.py", line 411, in _find_element
    return driver.find_element(*by)
AttributeError: 'str' object has no attribute 'find_element'
2020-08-25 14:30:28,721 [ERROR]: #  元素：百度-百度搜索框定位超时
Traceback (most recent call last):
  File "D:\sktest\common\locator.py", line 25, in locating_element
    element_location = wait.until(EC.presence_of_element_located((getattr(By, el_['by'].upper()), value)))
  File "D:\sktest\venv\lib\site-packages\selenium\webdriver\support\wait.py", line 71, in until
    value = method(self._driver)
  File "D:\sktest\venv\lib\site-packages\selenium\webdriver\support\expected_conditions.py", line 64, in __call__
    return _find_element(driver, self.locator)
  File "D:\sktest\venv\lib\site-packages\selenium\webdriver\support\expected_conditions.py", line 411, in _find_element
    return driver.find_element(*by)
AttributeError: 'str' object has no attribute 'find_element'

During handling of the above exception, another exception occurred:

Traceback (most recent call last):
  File "D:\sktest\common\locator.py", line 30, in locating_element
    element_location = wait.until(EC.presence_of_element_located((getattr(By, el_['by'].upper()), value)))
  File "D:\sktest\venv\lib\site-packages\selenium\webdriver\support\wait.py", line 71, in until
    value = method(self._driver)
  File "D:\sktest\venv\lib\site-packages\selenium\webdriver\support\expected_conditions.py", line 64, in __call__
    return _find_element(driver, self.locator)
  File "D:\sktest\venv\lib\site-packages\selenium\webdriver\support\expected_conditions.py", line 411, in _find_element
    return driver.find_element(*by)
AttributeError: 'str' object has no attribute 'find_element'
2020-08-25 14:30:28,722 [INFO]: #  Run The Step: 2|INPUT|百度-百度搜索框 Fail
2020-08-25 14:30:28,722 [INFO]: #  Run The Step: 3|CLICK|百度搜索按钮
2020-08-25 14:30:28,722 [ERROR]: #  元素：百度-百度搜索按钮第一次定位失败，等待三秒重试！！！
Traceback (most recent call last):
  File "D:\sktest\common\locator.py", line 25, in locating_element
    element_location = wait.until(EC.presence_of_element_located((getattr(By, el_['by'].upper()), value)))
  File "D:\sktest\venv\lib\site-packages\selenium\webdriver\support\wait.py", line 71, in until
    value = method(self._driver)
  File "D:\sktest\venv\lib\site-packages\selenium\webdriver\support\expected_conditions.py", line 64, in __call__
    return _find_element(driver, self.locator)
  File "D:\sktest\venv\lib\site-packages\selenium\webdriver\support\expected_conditions.py", line 411, in _find_element
    return driver.find_element(*by)
AttributeError: 'str' object has no attribute 'find_element'
2020-08-25 14:30:31,738 [ERROR]: #  元素：百度-百度搜索按钮定位超时
Traceback (most recent call last):
  File "D:\sktest\common\locator.py", line 25, in locating_element
    element_location = wait.until(EC.presence_of_element_located((getattr(By, el_['by'].upper()), value)))
  File "D:\sktest\venv\lib\site-packages\selenium\webdriver\support\wait.py", line 71, in until
    value = method(self._driver)
  File "D:\sktest\venv\lib\site-packages\selenium\webdriver\support\expected_conditions.py", line 64, in __call__
    return _find_element(driver, self.locator)
  File "D:\sktest\venv\lib\site-packages\selenium\webdriver\support\expected_conditions.py", line 411, in _find_element
    return driver.find_element(*by)
AttributeError: 'str' object has no attribute 'find_element'

During handling of the above exception, another exception occurred:

Traceback (most recent call last):
  File "D:\sktest\common\locator.py", line 30, in locating_element
    element_location = wait.until(EC.presence_of_element_located((getattr(By, el_['by'].upper()), value)))
  File "D:\sktest\venv\lib\site-packages\selenium\webdriver\support\wait.py", line 71, in until
    value = method(self._driver)
  File "D:\sktest\venv\lib\site-packages\selenium\webdriver\support\expected_conditions.py", line 64, in __call__
    return _find_element(driver, self.locator)
  File "D:\sktest\venv\lib\site-packages\selenium\webdriver\support\expected_conditions.py", line 411, in _find_element
    return driver.find_element(*by)
AttributeError: 'str' object has no attribute 'find_element'
2020-08-25 14:30:31,740 [INFO]: #  Run The Step: 3|CLICK|百度-百度搜索按钮 Fail
2020-08-25 14:30:32,249 [INFO]: #  ****  用例执行完成  ****
2020-08-25 14:30:32,249 [INFO]: #  **** 解析用例成功 ****
2020-08-25 14:30:32,249 [INFO]: #  -------- Run The TestCase：test-2 打开搜狗
2020-08-25 14:30:32,249 [INFO]: #  Run The Step: 1|OPEN|搜狗链接
2020-08-25 14:30:32,249 [INFO]: #  Run The Step: 1|OPEN|搜狗-搜狗链接 Fail
2020-08-25 14:30:32,760 [INFO]: #  ****  用例执行完成  ****
2020-08-25 14:30:37,493 [INFO]: #  **** 从Excel导入用例套件成功 ****
2020-08-25 14:30:37,493 [INFO]: #  **** 解析用例成功 ****
2020-08-25 14:30:37,493 [INFO]: #  -------- Run The TestCase：test-1 验证码登录运营中台
2020-08-25 14:30:37,493 [INFO]: #  Run The Step: 1|OPEN|百度搜索链接
2020-08-25 14:30:37,493 [INFO]: #  Run The Step: 1|OPEN|百度-百度搜索链接 Fail
2020-08-25 14:30:37,493 [INFO]: #  Run The Step: 2|INPUT|百度搜索框
2020-08-25 14:30:37,493 [ERROR]: #  元素：百度-百度搜索框第一次定位失败，等待三秒重试！！！
Traceback (most recent call last):
  File "D:\sktest\common\locator.py", line 25, in locating_element
    element_location = wait.until(EC.presence_of_element_located((getattr(By, el_['by'].upper()), value)))
  File "D:\sktest\venv\lib\site-packages\selenium\webdriver\support\wait.py", line 71, in until
    value = method(self._driver)
  File "D:\sktest\venv\lib\site-packages\selenium\webdriver\support\expected_conditions.py", line 64, in __call__
    return _find_element(driver, self.locator)
  File "D:\sktest\venv\lib\site-packages\selenium\webdriver\support\expected_conditions.py", line 411, in _find_element
    return driver.find_element(*by)
AttributeError: 'str' object has no attribute 'find_element'
2020-08-25 14:30:40,495 [ERROR]: #  元素：百度-百度搜索框定位超时
Traceback (most recent call last):
  File "D:\sktest\common\locator.py", line 25, in locating_element
    element_location = wait.until(EC.presence_of_element_located((getattr(By, el_['by'].upper()), value)))
  File "D:\sktest\venv\lib\site-packages\selenium\webdriver\support\wait.py", line 71, in until
    value = method(self._driver)
  File "D:\sktest\venv\lib\site-packages\selenium\webdriver\support\expected_conditions.py", line 64, in __call__
    return _find_element(driver, self.locator)
  File "D:\sktest\venv\lib\site-packages\selenium\webdriver\support\expected_conditions.py", line 411, in _find_element
    return driver.find_element(*by)
AttributeError: 'str' object has no attribute 'find_element'

During handling of the above exception, another exception occurred:

Traceback (most recent call last):
  File "D:\sktest\common\locator.py", line 30, in locating_element
    element_location = wait.until(EC.presence_of_element_located((getattr(By, el_['by'].upper()), value)))
  File "D:\sktest\venv\lib\site-packages\selenium\webdriver\support\wait.py", line 71, in until
    value = method(self._driver)
  File "D:\sktest\venv\lib\site-packages\selenium\webdriver\support\expected_conditions.py", line 64, in __call__
    return _find_element(driver, self.locator)
  File "D:\sktest\venv\lib\site-packages\selenium\webdriver\support\expected_conditions.py", line 411, in _find_element
    return driver.find_element(*by)
AttributeError: 'str' object has no attribute 'find_element'
2020-08-25 14:30:40,497 [INFO]: #  Run The Step: 2|INPUT|百度-百度搜索框 Fail
2020-08-25 14:30:40,497 [INFO]: #  Run The Step: 3|CLICK|百度搜索按钮
2020-08-25 14:30:40,498 [ERROR]: #  元素：百度-百度搜索按钮第一次定位失败，等待三秒重试！！！
Traceback (most recent call last):
  File "D:\sktest\common\locator.py", line 25, in locating_element
    element_location = wait.until(EC.presence_of_element_located((getattr(By, el_['by'].upper()), value)))
  File "D:\sktest\venv\lib\site-packages\selenium\webdriver\support\wait.py", line 71, in until
    value = method(self._driver)
  File "D:\sktest\venv\lib\site-packages\selenium\webdriver\support\expected_conditions.py", line 64, in __call__
    return _find_element(driver, self.locator)
  File "D:\sktest\venv\lib\site-packages\selenium\webdriver\support\expected_conditions.py", line 411, in _find_element
    return driver.find_element(*by)
AttributeError: 'str' object has no attribute 'find_element'
2020-08-25 14:30:43,509 [ERROR]: #  元素：百度-百度搜索按钮定位超时
Traceback (most recent call last):
  File "D:\sktest\common\locator.py", line 25, in locating_element
    element_location = wait.until(EC.presence_of_element_located((getattr(By, el_['by'].upper()), value)))
  File "D:\sktest\venv\lib\site-packages\selenium\webdriver\support\wait.py", line 71, in until
    value = method(self._driver)
  File "D:\sktest\venv\lib\site-packages\selenium\webdriver\support\expected_conditions.py", line 64, in __call__
    return _find_element(driver, self.locator)
  File "D:\sktest\venv\lib\site-packages\selenium\webdriver\support\expected_conditions.py", line 411, in _find_element
    return driver.find_element(*by)
AttributeError: 'str' object has no attribute 'find_element'

During handling of the above exception, another exception occurred:

Traceback (most recent call last):
  File "D:\sktest\common\locator.py", line 30, in locating_element
    element_location = wait.until(EC.presence_of_element_located((getattr(By, el_['by'].upper()), value)))
  File "D:\sktest\venv\lib\site-packages\selenium\webdriver\support\wait.py", line 71, in until
    value = method(self._driver)
  File "D:\sktest\venv\lib\site-packages\selenium\webdriver\support\expected_conditions.py", line 64, in __call__
    return _find_element(driver, self.locator)
  File "D:\sktest\venv\lib\site-packages\selenium\webdriver\support\expected_conditions.py", line 411, in _find_element
    return driver.find_element(*by)
AttributeError: 'str' object has no attribute 'find_element'
2020-08-25 14:30:43,509 [INFO]: #  Run The Step: 3|CLICK|百度-百度搜索按钮 Fail
2020-08-25 14:30:44,023 [INFO]: #  ****  用例执行完成  ****
2020-08-25 14:30:44,023 [INFO]: #  **** 解析用例成功 ****
2020-08-25 14:30:44,023 [INFO]: #  -------- Run The TestCase：test-2 打开搜狗
2020-08-25 14:30:44,023 [INFO]: #  Run The Step: 1|OPEN|搜狗链接
2020-08-25 14:30:44,023 [INFO]: #  Run The Step: 1|OPEN|搜狗-搜狗链接 Fail
2020-08-25 14:30:44,540 [INFO]: #  ****  用例执行完成  ****
2020-08-25 14:31:01,424 [INFO]: #  **** 从Excel导入用例套件成功 ****
2020-08-25 14:31:01,425 [INFO]: #  **** 解析用例成功 ****
2020-08-25 14:31:01,425 [INFO]: #  -------- Run The TestCase：test-1 验证码登录运营中台
2020-08-25 14:31:01,425 [INFO]: #  Run The Step: 1|OPEN|百度搜索链接
2020-08-25 14:31:01,425 [INFO]: #  Run The Step: 1|OPEN|百度-百度搜索链接 Fail
2020-08-25 14:31:01,425 [INFO]: #  Run The Step: 2|INPUT|百度搜索框
2020-08-25 14:31:01,425 [ERROR]: #  元素：百度-百度搜索框第一次定位失败，等待三秒重试！！！
Traceback (most recent call last):
  File "D:\sktest\common\locator.py", line 25, in locating_element
    element_location = wait.until(EC.presence_of_element_located((getattr(By, el_['by'].upper()), value)))
  File "D:\sktest\venv\lib\site-packages\selenium\webdriver\support\wait.py", line 71, in until
    value = method(self._driver)
  File "D:\sktest\venv\lib\site-packages\selenium\webdriver\support\expected_conditions.py", line 64, in __call__
    return _find_element(driver, self.locator)
  File "D:\sktest\venv\lib\site-packages\selenium\webdriver\support\expected_conditions.py", line 411, in _find_element
    return driver.find_element(*by)
AttributeError: 'str' object has no attribute 'find_element'
2020-08-25 14:31:04,432 [ERROR]: #  元素：百度-百度搜索框定位超时
Traceback (most recent call last):
  File "D:\sktest\common\locator.py", line 25, in locating_element
    element_location = wait.until(EC.presence_of_element_located((getattr(By, el_['by'].upper()), value)))
  File "D:\sktest\venv\lib\site-packages\selenium\webdriver\support\wait.py", line 71, in until
    value = method(self._driver)
  File "D:\sktest\venv\lib\site-packages\selenium\webdriver\support\expected_conditions.py", line 64, in __call__
    return _find_element(driver, self.locator)
  File "D:\sktest\venv\lib\site-packages\selenium\webdriver\support\expected_conditions.py", line 411, in _find_element
    return driver.find_element(*by)
AttributeError: 'str' object has no attribute 'find_element'

During handling of the above exception, another exception occurred:

Traceback (most recent call last):
  File "D:\sktest\common\locator.py", line 30, in locating_element
    element_location = wait.until(EC.presence_of_element_located((getattr(By, el_['by'].upper()), value)))
  File "D:\sktest\venv\lib\site-packages\selenium\webdriver\support\wait.py", line 71, in until
    value = method(self._driver)
  File "D:\sktest\venv\lib\site-packages\selenium\webdriver\support\expected_conditions.py", line 64, in __call__
    return _find_element(driver, self.locator)
  File "D:\sktest\venv\lib\site-packages\selenium\webdriver\support\expected_conditions.py", line 411, in _find_element
    return driver.find_element(*by)
AttributeError: 'str' object has no attribute 'find_element'
2020-08-25 14:31:04,435 [INFO]: #  Run The Step: 2|INPUT|百度-百度搜索框 Fail
2020-08-25 14:31:04,435 [INFO]: #  Run The Step: 3|CLICK|百度搜索按钮
2020-08-25 14:31:04,435 [ERROR]: #  元素：百度-百度搜索按钮第一次定位失败，等待三秒重试！！！
Traceback (most recent call last):
  File "D:\sktest\common\locator.py", line 25, in locating_element
    element_location = wait.until(EC.presence_of_element_located((getattr(By, el_['by'].upper()), value)))
  File "D:\sktest\venv\lib\site-packages\selenium\webdriver\support\wait.py", line 71, in until
    value = method(self._driver)
  File "D:\sktest\venv\lib\site-packages\selenium\webdriver\support\expected_conditions.py", line 64, in __call__
    return _find_element(driver, self.locator)
  File "D:\sktest\venv\lib\site-packages\selenium\webdriver\support\expected_conditions.py", line 411, in _find_element
    return driver.find_element(*by)
AttributeError: 'str' object has no attribute 'find_element'
2020-08-25 14:31:07,449 [ERROR]: #  元素：百度-百度搜索按钮定位超时
Traceback (most recent call last):
  File "D:\sktest\common\locator.py", line 25, in locating_element
    element_location = wait.until(EC.presence_of_element_located((getattr(By, el_['by'].upper()), value)))
  File "D:\sktest\venv\lib\site-packages\selenium\webdriver\support\wait.py", line 71, in until
    value = method(self._driver)
  File "D:\sktest\venv\lib\site-packages\selenium\webdriver\support\expected_conditions.py", line 64, in __call__
    return _find_element(driver, self.locator)
  File "D:\sktest\venv\lib\site-packages\selenium\webdriver\support\expected_conditions.py", line 411, in _find_element
    return driver.find_element(*by)
AttributeError: 'str' object has no attribute 'find_element'

During handling of the above exception, another exception occurred:

Traceback (most recent call last):
  File "D:\sktest\common\locator.py", line 30, in locating_element
    element_location = wait.until(EC.presence_of_element_located((getattr(By, el_['by'].upper()), value)))
  File "D:\sktest\venv\lib\site-packages\selenium\webdriver\support\wait.py", line 71, in until
    value = method(self._driver)
  File "D:\sktest\venv\lib\site-packages\selenium\webdriver\support\expected_conditions.py", line 64, in __call__
    return _find_element(driver, self.locator)
  File "D:\sktest\venv\lib\site-packages\selenium\webdriver\support\expected_conditions.py", line 411, in _find_element
    return driver.find_element(*by)
AttributeError: 'str' object has no attribute 'find_element'
2020-08-25 14:31:07,452 [INFO]: #  Run The Step: 3|CLICK|百度-百度搜索按钮 Fail
2020-08-25 14:31:07,964 [INFO]: #  ****  用例执行完成  ****
2020-08-25 14:31:07,964 [INFO]: #  **** 解析用例成功 ****
2020-08-25 14:31:07,964 [INFO]: #  -------- Run The TestCase：test-2 打开搜狗
2020-08-25 14:31:07,965 [INFO]: #  Run The Step: 1|OPEN|搜狗链接
2020-08-25 14:31:07,965 [INFO]: #  Run The Step: 1|OPEN|搜狗-搜狗链接 Fail
2020-08-25 14:31:08,476 [INFO]: #  ****  用例执行完成  ****
2020-08-25 14:31:20,384 [INFO]: #  **** 从Excel导入用例套件成功 ****
2020-08-25 14:31:20,384 [INFO]: #  **** 解析用例成功 ****
2020-08-25 14:31:20,384 [INFO]: #  -------- Run The TestCase：test-1 验证码登录运营中台
2020-08-25 14:31:20,384 [INFO]: #  Run The Step: 1|OPEN|百度搜索链接
2020-08-25 14:31:20,384 [INFO]: #  Run The Step: 1|OPEN|百度-百度搜索链接 Fail
2020-08-25 14:31:20,384 [INFO]: #  Run The Step: 2|INPUT|百度搜索框
2020-08-25 14:31:20,384 [ERROR]: #  元素：百度-百度搜索框第一次定位失败，等待三秒重试！！！
Traceback (most recent call last):
  File "D:\sktest\common\locator.py", line 25, in locating_element
    element_location = wait.until(EC.presence_of_element_located((getattr(By, el_['by'].upper()), value)))
  File "D:\sktest\venv\lib\site-packages\selenium\webdriver\support\wait.py", line 71, in until
    value = method(self._driver)
  File "D:\sktest\venv\lib\site-packages\selenium\webdriver\support\expected_conditions.py", line 64, in __call__
    return _find_element(driver, self.locator)
  File "D:\sktest\venv\lib\site-packages\selenium\webdriver\support\expected_conditions.py", line 411, in _find_element
    return driver.find_element(*by)
AttributeError: 'str' object has no attribute 'find_element'
2020-08-25 14:31:23,388 [ERROR]: #  元素：百度-百度搜索框定位超时
Traceback (most recent call last):
  File "D:\sktest\common\locator.py", line 25, in locating_element
    element_location = wait.until(EC.presence_of_element_located((getattr(By, el_['by'].upper()), value)))
  File "D:\sktest\venv\lib\site-packages\selenium\webdriver\support\wait.py", line 71, in until
    value = method(self._driver)
  File "D:\sktest\venv\lib\site-packages\selenium\webdriver\support\expected_conditions.py", line 64, in __call__
    return _find_element(driver, self.locator)
  File "D:\sktest\venv\lib\site-packages\selenium\webdriver\support\expected_conditions.py", line 411, in _find_element
    return driver.find_element(*by)
AttributeError: 'str' object has no attribute 'find_element'

During handling of the above exception, another exception occurred:

Traceback (most recent call last):
  File "D:\sktest\common\locator.py", line 30, in locating_element
    element_location = wait.until(EC.presence_of_element_located((getattr(By, el_['by'].upper()), value)))
  File "D:\sktest\venv\lib\site-packages\selenium\webdriver\support\wait.py", line 71, in until
    value = method(self._driver)
  File "D:\sktest\venv\lib\site-packages\selenium\webdriver\support\expected_conditions.py", line 64, in __call__
    return _find_element(driver, self.locator)
  File "D:\sktest\venv\lib\site-packages\selenium\webdriver\support\expected_conditions.py", line 411, in _find_element
    return driver.find_element(*by)
AttributeError: 'str' object has no attribute 'find_element'
2020-08-25 14:31:23,389 [INFO]: #  Run The Step: 2|INPUT|百度-百度搜索框 Fail
2020-08-25 14:31:23,389 [INFO]: #  Run The Step: 3|CLICK|百度搜索按钮
2020-08-25 14:31:23,389 [ERROR]: #  元素：百度-百度搜索按钮第一次定位失败，等待三秒重试！！！
Traceback (most recent call last):
  File "D:\sktest\common\locator.py", line 25, in locating_element
    element_location = wait.until(EC.presence_of_element_located((getattr(By, el_['by'].upper()), value)))
  File "D:\sktest\venv\lib\site-packages\selenium\webdriver\support\wait.py", line 71, in until
    value = method(self._driver)
  File "D:\sktest\venv\lib\site-packages\selenium\webdriver\support\expected_conditions.py", line 64, in __call__
    return _find_element(driver, self.locator)
  File "D:\sktest\venv\lib\site-packages\selenium\webdriver\support\expected_conditions.py", line 411, in _find_element
    return driver.find_element(*by)
AttributeError: 'str' object has no attribute 'find_element'
2020-08-25 14:31:26,401 [ERROR]: #  元素：百度-百度搜索按钮定位超时
Traceback (most recent call last):
  File "D:\sktest\common\locator.py", line 25, in locating_element
    element_location = wait.until(EC.presence_of_element_located((getattr(By, el_['by'].upper()), value)))
  File "D:\sktest\venv\lib\site-packages\selenium\webdriver\support\wait.py", line 71, in until
    value = method(self._driver)
  File "D:\sktest\venv\lib\site-packages\selenium\webdriver\support\expected_conditions.py", line 64, in __call__
    return _find_element(driver, self.locator)
  File "D:\sktest\venv\lib\site-packages\selenium\webdriver\support\expected_conditions.py", line 411, in _find_element
    return driver.find_element(*by)
AttributeError: 'str' object has no attribute 'find_element'

During handling of the above exception, another exception occurred:

Traceback (most recent call last):
  File "D:\sktest\common\locator.py", line 30, in locating_element
    element_location = wait.until(EC.presence_of_element_located((getattr(By, el_['by'].upper()), value)))
  File "D:\sktest\venv\lib\site-packages\selenium\webdriver\support\wait.py", line 71, in until
    value = method(self._driver)
  File "D:\sktest\venv\lib\site-packages\selenium\webdriver\support\expected_conditions.py", line 64, in __call__
    return _find_element(driver, self.locator)
  File "D:\sktest\venv\lib\site-packages\selenium\webdriver\support\expected_conditions.py", line 411, in _find_element
    return driver.find_element(*by)
AttributeError: 'str' object has no attribute 'find_element'
2020-08-25 14:31:26,403 [INFO]: #  Run The Step: 3|CLICK|百度-百度搜索按钮 Fail
2020-08-25 14:31:26,915 [INFO]: #  ****  用例执行完成  ****
2020-08-25 14:31:26,915 [INFO]: #  **** 解析用例成功 ****
2020-08-25 14:31:26,915 [INFO]: #  -------- Run The TestCase：test-2 打开搜狗
2020-08-25 14:31:26,916 [INFO]: #  Run The Step: 1|OPEN|搜狗链接
2020-08-25 14:31:26,916 [INFO]: #  Run The Step: 1|OPEN|搜狗-搜狗链接 Fail
2020-08-25 14:31:27,431 [INFO]: #  ****  用例执行完成  ****
2020-08-25 14:33:29,087 [ERROR]: #  #### driver 初始化失败！@浏览器类型不支持
NoneType: None
2020-08-25 14:33:29,087 [ERROR]: #  #### driver 初始化失败！@或许你需要检查executable_path配置！！！
Traceback (most recent call last):
  File "D:\sktest\common\globals.py", line 29, in init
    raise Exception("ERR: 不支持的浏览器类型%s" % self.browser)
Exception: ERR: 不支持的浏览器类型Chrom
2020-08-25 14:34:27,596 [ERROR]: #  #### driver 初始化失败！@浏览器类型不支持
NoneType: None
2020-08-25 14:34:27,596 [ERROR]: #  #### driver 初始化失败！@或许你需要检查executable_path配置！！！
Traceback (most recent call last):
  File "D:\sktest\common\globals.py", line 30, in init
    raise Exception("ERR: 不支持的浏览器类型%s" % self.browser)
Exception: ERR: 不支持的浏览器类型Chrom
2020-08-25 14:35:35,614 [ERROR]: #  #### driver 初始化失败！@浏览器类型不支持
NoneType: None
2020-08-25 14:35:35,614 [INFO]: #  **** 从Excel导入用例套件成功 ****
2020-08-25 14:35:35,614 [INFO]: #  **** 解析用例成功 ****
2020-08-25 14:35:35,614 [INFO]: #  -------- Run The TestCase：test-1 验证码登录运营中台
2020-08-25 14:35:35,614 [INFO]: #  Run The Step: 1|OPEN|百度搜索链接
2020-08-25 14:35:35,614 [INFO]: #  Run The Step: 1|OPEN|百度-百度搜索链接 Fail
2020-08-25 14:35:35,614 [INFO]: #  Run The Step: 2|INPUT|百度搜索框
2020-08-25 14:35:35,614 [ERROR]: #  元素：百度-百度搜索框第一次定位失败，等待三秒重试！！！
Traceback (most recent call last):
  File "D:\sktest\common\locator.py", line 25, in locating_element
    element_location = wait.until(EC.presence_of_element_located((getattr(By, el_['by'].upper()), value)))
  File "D:\sktest\venv\lib\site-packages\selenium\webdriver\support\wait.py", line 71, in until
    value = method(self._driver)
  File "D:\sktest\venv\lib\site-packages\selenium\webdriver\support\expected_conditions.py", line 64, in __call__
    return _find_element(driver, self.locator)
  File "D:\sktest\venv\lib\site-packages\selenium\webdriver\support\expected_conditions.py", line 411, in _find_element
    return driver.find_element(*by)
AttributeError: 'str' object has no attribute 'find_element'
2020-08-25 14:35:38,633 [ERROR]: #  元素：百度-百度搜索框定位超时
Traceback (most recent call last):
  File "D:\sktest\common\locator.py", line 25, in locating_element
    element_location = wait.until(EC.presence_of_element_located((getattr(By, el_['by'].upper()), value)))
  File "D:\sktest\venv\lib\site-packages\selenium\webdriver\support\wait.py", line 71, in until
    value = method(self._driver)
  File "D:\sktest\venv\lib\site-packages\selenium\webdriver\support\expected_conditions.py", line 64, in __call__
    return _find_element(driver, self.locator)
  File "D:\sktest\venv\lib\site-packages\selenium\webdriver\support\expected_conditions.py", line 411, in _find_element
    return driver.find_element(*by)
AttributeError: 'str' object has no attribute 'find_element'

During handling of the above exception, another exception occurred:

Traceback (most recent call last):
  File "D:\sktest\common\locator.py", line 30, in locating_element
    element_location = wait.until(EC.presence_of_element_located((getattr(By, el_['by'].upper()), value)))
  File "D:\sktest\venv\lib\site-packages\selenium\webdriver\support\wait.py", line 71, in until
    value = method(self._driver)
  File "D:\sktest\venv\lib\site-packages\selenium\webdriver\support\expected_conditions.py", line 64, in __call__
    return _find_element(driver, self.locator)
  File "D:\sktest\venv\lib\site-packages\selenium\webdriver\support\expected_conditions.py", line 411, in _find_element
    return driver.find_element(*by)
AttributeError: 'str' object has no attribute 'find_element'
2020-08-25 14:35:38,637 [INFO]: #  Run The Step: 2|INPUT|百度-百度搜索框 Fail
2020-08-25 14:35:38,637 [INFO]: #  Run The Step: 3|CLICK|百度搜索按钮
2020-08-25 14:35:38,637 [ERROR]: #  元素：百度-百度搜索按钮第一次定位失败，等待三秒重试！！！
Traceback (most recent call last):
  File "D:\sktest\common\locator.py", line 25, in locating_element
    element_location = wait.until(EC.presence_of_element_located((getattr(By, el_['by'].upper()), value)))
  File "D:\sktest\venv\lib\site-packages\selenium\webdriver\support\wait.py", line 71, in until
    value = method(self._driver)
  File "D:\sktest\venv\lib\site-packages\selenium\webdriver\support\expected_conditions.py", line 64, in __call__
    return _find_element(driver, self.locator)
  File "D:\sktest\venv\lib\site-packages\selenium\webdriver\support\expected_conditions.py", line 411, in _find_element
    return driver.find_element(*by)
AttributeError: 'str' object has no attribute 'find_element'
2020-08-25 14:35:41,656 [ERROR]: #  元素：百度-百度搜索按钮定位超时
Traceback (most recent call last):
  File "D:\sktest\common\locator.py", line 25, in locating_element
    element_location = wait.until(EC.presence_of_element_located((getattr(By, el_['by'].upper()), value)))
  File "D:\sktest\venv\lib\site-packages\selenium\webdriver\support\wait.py", line 71, in until
    value = method(self._driver)
  File "D:\sktest\venv\lib\site-packages\selenium\webdriver\support\expected_conditions.py", line 64, in __call__
    return _find_element(driver, self.locator)
  File "D:\sktest\venv\lib\site-packages\selenium\webdriver\support\expected_conditions.py", line 411, in _find_element
    return driver.find_element(*by)
AttributeError: 'str' object has no attribute 'find_element'

During handling of the above exception, another exception occurred:

Traceback (most recent call last):
  File "D:\sktest\common\locator.py", line 30, in locating_element
    element_location = wait.until(EC.presence_of_element_located((getattr(By, el_['by'].upper()), value)))
  File "D:\sktest\venv\lib\site-packages\selenium\webdriver\support\wait.py", line 71, in until
    value = method(self._driver)
  File "D:\sktest\venv\lib\site-packages\selenium\webdriver\support\expected_conditions.py", line 64, in __call__
    return _find_element(driver, self.locator)
  File "D:\sktest\venv\lib\site-packages\selenium\webdriver\support\expected_conditions.py", line 411, in _find_element
    return driver.find_element(*by)
AttributeError: 'str' object has no attribute 'find_element'
2020-08-25 14:35:41,660 [INFO]: #  Run The Step: 3|CLICK|百度-百度搜索按钮 Fail
2020-08-25 14:35:42,163 [INFO]: #  ****  用例执行完成  ****
2020-08-25 14:35:42,163 [INFO]: #  **** 解析用例成功 ****
2020-08-25 14:35:42,164 [INFO]: #  -------- Run The TestCase：test-2 打开搜狗
2020-08-25 14:35:42,164 [INFO]: #  Run The Step: 1|OPEN|搜狗链接
2020-08-25 14:35:42,164 [INFO]: #  Run The Step: 1|OPEN|搜狗-搜狗链接 Fail
2020-08-25 14:35:42,680 [INFO]: #  ****  用例执行完成  ****
2020-08-25 14:36:08,654 [ERROR]: #  #### driver 初始化失败！@浏览器类型不支持
NoneType: None
2020-08-25 14:36:08,661 [INFO]: #  **** 从Excel导入用例套件成功 ****
2020-08-25 14:36:08,661 [INFO]: #  **** 解析用例成功 ****
2020-08-25 14:36:08,661 [INFO]: #  -------- Run The TestCase：test-1 验证码登录运营中台
2020-08-25 14:36:08,661 [INFO]: #  Run The Step: 1|OPEN|百度搜索链接
2020-08-25 14:36:08,661 [INFO]: #  Run The Step: 1|OPEN|百度-百度搜索链接 Fail
2020-08-25 14:36:08,661 [INFO]: #  Run The Step: 2|INPUT|百度搜索框
2020-08-25 14:36:08,661 [ERROR]: #  元素：百度-百度搜索框第一次定位失败，等待三秒重试！！！
Traceback (most recent call last):
  File "D:\sktest\common\locator.py", line 25, in locating_element
    element_location = wait.until(EC.presence_of_element_located((getattr(By, el_['by'].upper()), value)))
  File "D:\sktest\venv\lib\site-packages\selenium\webdriver\support\wait.py", line 71, in until
    value = method(self._driver)
  File "D:\sktest\venv\lib\site-packages\selenium\webdriver\support\expected_conditions.py", line 64, in __call__
    return _find_element(driver, self.locator)
  File "D:\sktest\venv\lib\site-packages\selenium\webdriver\support\expected_conditions.py", line 411, in _find_element
    return driver.find_element(*by)
AttributeError: 'str' object has no attribute 'find_element'
2020-08-25 14:36:11,663 [ERROR]: #  元素：百度-百度搜索框定位超时
Traceback (most recent call last):
  File "D:\sktest\common\locator.py", line 25, in locating_element
    element_location = wait.until(EC.presence_of_element_located((getattr(By, el_['by'].upper()), value)))
  File "D:\sktest\venv\lib\site-packages\selenium\webdriver\support\wait.py", line 71, in until
    value = method(self._driver)
  File "D:\sktest\venv\lib\site-packages\selenium\webdriver\support\expected_conditions.py", line 64, in __call__
    return _find_element(driver, self.locator)
  File "D:\sktest\venv\lib\site-packages\selenium\webdriver\support\expected_conditions.py", line 411, in _find_element
    return driver.find_element(*by)
AttributeError: 'str' object has no attribute 'find_element'

During handling of the above exception, another exception occurred:

Traceback (most recent call last):
  File "D:\sktest\common\locator.py", line 30, in locating_element
    element_location = wait.until(EC.presence_of_element_located((getattr(By, el_['by'].upper()), value)))
  File "D:\sktest\venv\lib\site-packages\selenium\webdriver\support\wait.py", line 71, in until
    value = method(self._driver)
  File "D:\sktest\venv\lib\site-packages\selenium\webdriver\support\expected_conditions.py", line 64, in __call__
    return _find_element(driver, self.locator)
  File "D:\sktest\venv\lib\site-packages\selenium\webdriver\support\expected_conditions.py", line 411, in _find_element
    return driver.find_element(*by)
AttributeError: 'str' object has no attribute 'find_element'
2020-08-25 14:36:11,666 [INFO]: #  Run The Step: 2|INPUT|百度-百度搜索框 Fail
2020-08-25 14:36:11,666 [INFO]: #  Run The Step: 3|CLICK|百度搜索按钮
2020-08-25 14:36:11,666 [ERROR]: #  元素：百度-百度搜索按钮第一次定位失败，等待三秒重试！！！
Traceback (most recent call last):
  File "D:\sktest\common\locator.py", line 25, in locating_element
    element_location = wait.until(EC.presence_of_element_located((getattr(By, el_['by'].upper()), value)))
  File "D:\sktest\venv\lib\site-packages\selenium\webdriver\support\wait.py", line 71, in until
    value = method(self._driver)
  File "D:\sktest\venv\lib\site-packages\selenium\webdriver\support\expected_conditions.py", line 64, in __call__
    return _find_element(driver, self.locator)
  File "D:\sktest\venv\lib\site-packages\selenium\webdriver\support\expected_conditions.py", line 411, in _find_element
    return driver.find_element(*by)
AttributeError: 'str' object has no attribute 'find_element'
2020-08-25 14:36:14,684 [ERROR]: #  元素：百度-百度搜索按钮定位超时
Traceback (most recent call last):
  File "D:\sktest\common\locator.py", line 25, in locating_element
    element_location = wait.until(EC.presence_of_element_located((getattr(By, el_['by'].upper()), value)))
  File "D:\sktest\venv\lib\site-packages\selenium\webdriver\support\wait.py", line 71, in until
    value = method(self._driver)
  File "D:\sktest\venv\lib\site-packages\selenium\webdriver\support\expected_conditions.py", line 64, in __call__
    return _find_element(driver, self.locator)
  File "D:\sktest\venv\lib\site-packages\selenium\webdriver\support\expected_conditions.py", line 411, in _find_element
    return driver.find_element(*by)
AttributeError: 'str' object has no attribute 'find_element'

During handling of the above exception, another exception occurred:

Traceback (most recent call last):
  File "D:\sktest\common\locator.py", line 30, in locating_element
    element_location = wait.until(EC.presence_of_element_located((getattr(By, el_['by'].upper()), value)))
  File "D:\sktest\venv\lib\site-packages\selenium\webdriver\support\wait.py", line 71, in until
    value = method(self._driver)
  File "D:\sktest\venv\lib\site-packages\selenium\webdriver\support\expected_conditions.py", line 64, in __call__
    return _find_element(driver, self.locator)
  File "D:\sktest\venv\lib\site-packages\selenium\webdriver\support\expected_conditions.py", line 411, in _find_element
    return driver.find_element(*by)
AttributeError: 'str' object has no attribute 'find_element'
2020-08-25 14:36:14,686 [INFO]: #  Run The Step: 3|CLICK|百度-百度搜索按钮 Fail
2020-08-25 14:36:15,193 [INFO]: #  ****  用例执行完成  ****
2020-08-25 14:36:15,193 [INFO]: #  **** 解析用例成功 ****
2020-08-25 14:36:15,193 [INFO]: #  -------- Run The TestCase：test-2 打开搜狗
2020-08-25 14:36:15,193 [INFO]: #  Run The Step: 1|OPEN|搜狗链接
2020-08-25 14:36:15,193 [INFO]: #  Run The Step: 1|OPEN|搜狗-搜狗链接 Fail
2020-08-25 14:36:15,694 [INFO]: #  ****  用例执行完成  ****
2020-08-25 14:37:00,446 [ERROR]: #  #### driver 初始化失败！@浏览器类型不支持
NoneType: None
2020-08-25 14:37:00,446 [ERROR]: #  #### driver 初始化失败！@或许你需要检查executable_path配置！！！
Traceback (most recent call last):
  File "D:\sktest\common\globals.py", line 30, in init
    raise Exception("ERR: 不支持的浏览器类型")
Exception: ERR: 不支持的浏览器类型
2020-08-25 14:39:23,161 [ERROR]: #  #### driver 初始化失败！@或许你需要检查executable_path配置！！！
Traceback (most recent call last):
  File "D:\sktest\common\globals.py", line 30, in init
    raise Exception("ERR: browser err")
Exception: ERR: browser err
2020-08-25 14:44:52,709 [ERROR]: #  this browser is not supported or mistake nameChrom 
NoneType: None
2020-08-25 14:44:52,709 [INFO]: #  **** 从Excel导入用例套件成功 ****
2020-08-25 14:44:52,709 [INFO]: #  **** 解析用例成功 ****
2020-08-25 14:44:52,709 [INFO]: #  -------- Run The TestCase：test-1 验证码登录运营中台
2020-08-25 14:44:52,709 [INFO]: #  Run The Step: 1|OPEN|百度搜索链接
2020-08-25 14:44:52,709 [INFO]: #  Run The Step: 1|OPEN|百度-百度搜索链接 Fail
2020-08-25 14:44:52,709 [INFO]: #  Run The Step: 2|INPUT|百度搜索框
2020-08-25 14:44:52,709 [ERROR]: #  元素：百度-百度搜索框第一次定位失败，等待三秒重试！！！
Traceback (most recent call last):
  File "D:\sktest\common\locator.py", line 25, in locating_element
    element_location = wait.until(EC.presence_of_element_located((getattr(By, el_['by'].upper()), value)))
  File "D:\sktest\venv\lib\site-packages\selenium\webdriver\support\wait.py", line 71, in until
    value = method(self._driver)
  File "D:\sktest\venv\lib\site-packages\selenium\webdriver\support\expected_conditions.py", line 64, in __call__
    return _find_element(driver, self.locator)
  File "D:\sktest\venv\lib\site-packages\selenium\webdriver\support\expected_conditions.py", line 411, in _find_element
    return driver.find_element(*by)
AttributeError: 'str' object has no attribute 'find_element'
2020-08-25 14:44:55,711 [ERROR]: #  元素：百度-百度搜索框定位超时
Traceback (most recent call last):
  File "D:\sktest\common\locator.py", line 25, in locating_element
    element_location = wait.until(EC.presence_of_element_located((getattr(By, el_['by'].upper()), value)))
  File "D:\sktest\venv\lib\site-packages\selenium\webdriver\support\wait.py", line 71, in until
    value = method(self._driver)
  File "D:\sktest\venv\lib\site-packages\selenium\webdriver\support\expected_conditions.py", line 64, in __call__
    return _find_element(driver, self.locator)
  File "D:\sktest\venv\lib\site-packages\selenium\webdriver\support\expected_conditions.py", line 411, in _find_element
    return driver.find_element(*by)
AttributeError: 'str' object has no attribute 'find_element'

During handling of the above exception, another exception occurred:

Traceback (most recent call last):
  File "D:\sktest\common\locator.py", line 30, in locating_element
    element_location = wait.until(EC.presence_of_element_located((getattr(By, el_['by'].upper()), value)))
  File "D:\sktest\venv\lib\site-packages\selenium\webdriver\support\wait.py", line 71, in until
    value = method(self._driver)
  File "D:\sktest\venv\lib\site-packages\selenium\webdriver\support\expected_conditions.py", line 64, in __call__
    return _find_element(driver, self.locator)
  File "D:\sktest\venv\lib\site-packages\selenium\webdriver\support\expected_conditions.py", line 411, in _find_element
    return driver.find_element(*by)
AttributeError: 'str' object has no attribute 'find_element'
2020-08-25 14:44:55,712 [INFO]: #  Run The Step: 2|INPUT|百度-百度搜索框 Fail
2020-08-25 14:44:55,712 [INFO]: #  Run The Step: 3|CLICK|百度搜索按钮
2020-08-25 14:44:55,712 [ERROR]: #  元素：百度-百度搜索按钮第一次定位失败，等待三秒重试！！！
Traceback (most recent call last):
  File "D:\sktest\common\locator.py", line 25, in locating_element
    element_location = wait.until(EC.presence_of_element_located((getattr(By, el_['by'].upper()), value)))
  File "D:\sktest\venv\lib\site-packages\selenium\webdriver\support\wait.py", line 71, in until
    value = method(self._driver)
  File "D:\sktest\venv\lib\site-packages\selenium\webdriver\support\expected_conditions.py", line 64, in __call__
    return _find_element(driver, self.locator)
  File "D:\sktest\venv\lib\site-packages\selenium\webdriver\support\expected_conditions.py", line 411, in _find_element
    return driver.find_element(*by)
AttributeError: 'str' object has no attribute 'find_element'
2020-08-25 14:44:58,713 [ERROR]: #  元素：百度-百度搜索按钮定位超时
Traceback (most recent call last):
  File "D:\sktest\common\locator.py", line 25, in locating_element
    element_location = wait.until(EC.presence_of_element_located((getattr(By, el_['by'].upper()), value)))
  File "D:\sktest\venv\lib\site-packages\selenium\webdriver\support\wait.py", line 71, in until
    value = method(self._driver)
  File "D:\sktest\venv\lib\site-packages\selenium\webdriver\support\expected_conditions.py", line 64, in __call__
    return _find_element(driver, self.locator)
  File "D:\sktest\venv\lib\site-packages\selenium\webdriver\support\expected_conditions.py", line 411, in _find_element
    return driver.find_element(*by)
AttributeError: 'str' object has no attribute 'find_element'

During handling of the above exception, another exception occurred:

Traceback (most recent call last):
  File "D:\sktest\common\locator.py", line 30, in locating_element
    element_location = wait.until(EC.presence_of_element_located((getattr(By, el_['by'].upper()), value)))
  File "D:\sktest\venv\lib\site-packages\selenium\webdriver\support\wait.py", line 71, in until
    value = method(self._driver)
  File "D:\sktest\venv\lib\site-packages\selenium\webdriver\support\expected_conditions.py", line 64, in __call__
    return _find_element(driver, self.locator)
  File "D:\sktest\venv\lib\site-packages\selenium\webdriver\support\expected_conditions.py", line 411, in _find_element
    return driver.find_element(*by)
AttributeError: 'str' object has no attribute 'find_element'
2020-08-25 14:44:58,714 [INFO]: #  Run The Step: 3|CLICK|百度-百度搜索按钮 Fail
2020-08-25 14:44:59,228 [INFO]: #  ****  用例执行完成  ****
2020-08-25 14:44:59,228 [INFO]: #  **** 解析用例成功 ****
2020-08-25 14:44:59,229 [INFO]: #  -------- Run The TestCase：test-2 打开搜狗
2020-08-25 14:44:59,229 [INFO]: #  Run The Step: 1|OPEN|搜狗链接
2020-08-25 14:44:59,229 [INFO]: #  Run The Step: 1|OPEN|搜狗-搜狗链接 Fail
2020-08-25 14:44:59,738 [INFO]: #  ****  用例执行完成  ****
2020-08-25 15:01:07,841 [INFO]: #  **** 从Excel导入用例套件成功 ****
2020-08-25 15:01:07,841 [INFO]: #  **** 解析用例成功 ****
2020-08-25 15:01:07,841 [INFO]: #  -------- Run The TestCase：test-1 验证码登录运营中台
2020-08-25 15:01:07,841 [INFO]: #  Run The Step: 1|OPEN|百度搜索链接
2020-08-25 15:01:08,964 [INFO]: #  Run The Step: 1|OPEN|百度-百度搜索链接 Success
2020-08-25 15:01:09,265 [INFO]: #  Run The Step: 2|INPUT|百度搜索框
2020-08-25 15:01:09,845 [INFO]: #  Run The Step: 2|INPUT|百度-百度搜索框 Success
2020-08-25 15:01:10,154 [INFO]: #  Run The Step: 3|CLICK|百度搜索按钮
2020-08-25 15:01:10,704 [INFO]: #  Run The Step: 3|CLICK|百度-百度搜索按钮 Success
2020-08-25 15:01:11,528 [INFO]: #  ****  用例执行完成  ****
2020-08-25 15:01:11,528 [INFO]: #  **** 解析用例成功 ****
2020-08-25 15:01:11,528 [INFO]: #  -------- Run The TestCase：test-2 打开搜狗
2020-08-25 15:01:11,528 [INFO]: #  Run The Step: 1|OPEN|搜狗链接
2020-08-25 15:01:12,485 [INFO]: #  Run The Step: 1|OPEN|搜狗-搜狗链接 Success
2020-08-25 15:01:13,306 [INFO]: #  ****  用例执行完成  ****
2020-08-25 15:02:47,876 [INFO]: #  **** 从Excel导入用例套件成功 ****
2020-08-25 15:02:47,876 [INFO]: #  **** 解析用例成功 ****
2020-08-25 15:02:47,876 [INFO]: #  -------- Run The TestCase：test-1 验证码登录运营中台
2020-08-25 15:02:47,876 [INFO]: #  Run The Step: 1|OPEN|百度搜索链接
2020-08-25 15:02:48,930 [INFO]: #  Run The Step: 1|OPEN|百度-百度搜索链接 Success
2020-08-25 15:02:49,243 [INFO]: #  Run The Step: 2|INPUT|百度搜索框
2020-08-25 15:02:49,827 [INFO]: #  Run The Step: 2|INPUT|百度-百度搜索框 Success
2020-08-25 15:02:50,133 [INFO]: #  Run The Step: 3|CLICK|百度搜索按钮
2020-08-25 15:02:50,696 [INFO]: #  Run The Step: 3|CLICK|百度-百度搜索按钮 Success
2020-08-25 15:02:51,497 [INFO]: #  ****  用例执行完成  ****
2020-08-25 15:02:51,497 [INFO]: #  **** 解析用例成功 ****
2020-08-25 15:02:51,497 [INFO]: #  -------- Run The TestCase：test-2 打开搜狗
2020-08-25 15:02:51,497 [INFO]: #  Run The Step: 1|OPEN|搜狗链接
2020-08-25 15:02:52,469 [INFO]: #  Run The Step: 1|OPEN|搜狗-搜狗链接 Success
2020-08-25 15:02:53,270 [INFO]: #  ****  用例执行完成  ****
2020-08-25 15:04:06,169 [INFO]: #  **** 从Excel导入用例套件成功 ****
2020-08-25 15:04:06,169 [INFO]: #  **** 解析用例成功 ****
2020-08-25 15:04:06,169 [INFO]: #  -------- Run The TestCase：test-1 验证码登录运营中台
2020-08-25 15:04:06,169 [INFO]: #  Run The Step: 1|OPEN|百度搜索链接
2020-08-25 15:04:07,266 [INFO]: #  Run The Step: 1|OPEN|百度-百度搜索链接 Success
2020-08-25 15:04:07,581 [INFO]: #  Run The Step: 2|INPUT|百度搜索框
2020-08-25 15:04:08,166 [INFO]: #  Run The Step: 2|INPUT|百度-百度搜索框 Success
2020-08-25 15:04:08,476 [INFO]: #  Run The Step: 3|CLICK|百度搜索按钮
2020-08-25 15:04:09,036 [INFO]: #  Run The Step: 3|CLICK|百度-百度搜索按钮 Success
2020-08-25 15:04:09,849 [INFO]: #  ****  用例执行完成  ****
2020-08-25 15:04:09,849 [INFO]: #  **** 解析用例成功 ****
2020-08-25 15:04:09,850 [INFO]: #  -------- Run The TestCase：test-2 打开搜狗
2020-08-25 15:04:09,850 [INFO]: #  Run The Step: 1|OPEN|搜狗链接
2020-08-25 15:04:10,775 [INFO]: #  Run The Step: 1|OPEN|搜狗-搜狗链接 Success
2020-08-25 15:04:11,576 [INFO]: #  ****  用例执行完成  ****
2020-08-25 15:14:28,436 [INFO]: #  **** 从Excel导入用例套件成功 ****
2020-08-25 15:14:28,436 [INFO]: #  **** 解析用例成功 ****
2020-08-25 15:14:28,436 [INFO]: #  -------- Run The TestCase：test-1 验证码登录运营中台
2020-08-25 15:14:28,436 [INFO]: #  Run The Step: 1|OPEN|百度搜索链接
2020-08-25 15:14:29,494 [INFO]: #  Run The Step: 1|OPEN|百度-百度搜索链接 Success
2020-08-25 15:14:29,803 [INFO]: #  Run The Step: 2|INPUT|百度搜索框
2020-08-25 15:14:30,400 [INFO]: #  Run The Step: 2|INPUT|百度-百度搜索框 Success
2020-08-25 15:14:30,703 [INFO]: #  Run The Step: 3|CLICK|百度搜索按钮
2020-08-25 15:14:31,264 [INFO]: #  Run The Step: 3|CLICK|百度-百度搜索按钮 Success
2020-08-25 15:14:32,079 [INFO]: #  ****  用例执行完成  ****
2020-08-25 15:14:32,079 [INFO]: #  **** 解析用例成功 ****
2020-08-25 15:14:32,079 [INFO]: #  -------- Run The TestCase：test-2 打开搜狗
2020-08-25 15:14:32,079 [INFO]: #  Run The Step: 1|OPEN|搜狗链接
2020-08-25 15:14:33,021 [INFO]: #  Run The Step: 1|OPEN|搜狗-搜狗链接 Success
2020-08-25 15:14:33,822 [INFO]: #  ****  用例执行完成  ****
2020-08-25 16:03:43,944 [INFO]: #  **** 从Excel导入用例套件成功 ****
2020-08-25 16:03:43,944 [INFO]: #  **** 解析用例成功 ****
2020-08-25 16:03:43,944 [INFO]: #  -------- Run The TestCase：test-1 验证码登录运营中台
2020-08-25 16:03:43,944 [INFO]: #  Run The Step: 1|OPEN|百度搜索链接
2020-08-25 16:03:45,082 [INFO]: #  Run The Step: 1|OPEN|百度-百度搜索链接 Success
2020-08-25 16:03:45,382 [INFO]: #  Run The Step: 2|INPUT|百度搜索框
2020-08-25 16:03:45,983 [INFO]: #  Run The Step: 2|INPUT|百度-百度搜索框 Success
2020-08-25 16:03:46,284 [INFO]: #  Run The Step: 3|CLICK|百度搜索按钮
2020-08-25 16:03:46,861 [INFO]: #  Run The Step: 3|CLICK|百度-百度搜索按钮 Success
2020-08-25 16:03:47,672 [INFO]: #  ****  用例执行完成  ****
2020-08-25 16:03:47,672 [INFO]: #  **** 解析用例成功 ****
2020-08-25 16:03:47,672 [INFO]: #  -------- Run The TestCase：test-2 打开搜狗
2020-08-25 16:03:47,672 [INFO]: #  Run The Step: 1|OPEN|搜狗链接
2020-08-25 16:03:49,117 [INFO]: #  Run The Step: 1|OPEN|搜狗-搜狗链接 Success
2020-08-25 16:03:49,918 [INFO]: #  ****  用例执行完成  ****
2020-08-25 17:35:34,050 [INFO]: #  **** 从Excel导入用例套件成功 ****
2020-08-25 17:35:34,050 [INFO]: #  **** 解析用例成功 ****
2020-08-25 17:35:34,050 [INFO]: #  -------- Run The TestCase：test-1 打开百度
2020-08-25 17:35:34,050 [INFO]: #  Run The Step: 1|OPEN|百度搜索链接
2020-08-25 17:35:35,251 [INFO]: #  Run The Step: 1|OPEN|百度搜索页-百度搜索链接 Success
2020-08-25 17:35:35,553 [INFO]: #  Run The Step: 2|INPUT|百度搜索框
2020-08-25 17:35:36,144 [INFO]: #  Run The Step: 2|INPUT|百度搜索页-百度搜索框 Success
2020-08-25 17:35:36,445 [INFO]: #  Run The Step: 3|CLICK|百度搜索按钮
2020-08-25 17:35:37,013 [INFO]: #  Run The Step: 3|CLICK|百度搜索页-百度搜索按钮 Success
2020-08-25 17:35:37,819 [INFO]: #  ****  用例执行完成  ****
2020-08-25 17:37:44,106 [ERROR]: #  **** 从Excel导入用例套件失败 ****
Traceback (most recent call last):
  File "D:\sktest\sktest\autotest.py", line 30, in run
    self.test_case_workbook.close()
  File "D:\sktest\common\utility.py", line 39, in close
    self.workbook.close()
AttributeError: 'Book' object has no attribute 'close'
2020-08-25 17:50:14,536 [ERROR]: #  **** 从Excel导入用例套件失败 ****
Traceback (most recent call last):
  File "D:\sktest\sktest\autotest.py", line 30, in run
    self.test_case_workbook.close()
  File "D:\sktest\common\utility.py", line 40, in close
    self.workbook.close()
AttributeError: 'Book' object has no attribute 'close'
2020-08-25 17:50:31,196 [INFO]: #  **** 从Excel导入用例套件成功 ****
2020-08-25 17:50:31,196 [INFO]: #  **** 解析用例成功 ****
2020-08-25 17:50:31,197 [INFO]: #  -------- Run The TestCase：test-1 打开百度
2020-08-25 17:50:31,197 [INFO]: #  Run The Step: 1|OPEN|百度搜索链接
2020-08-25 17:50:32,622 [INFO]: #  Run The Step: 1|OPEN|百度搜索页-百度搜索链接 Success
2020-08-25 17:50:32,922 [INFO]: #  Run The Step: 2|INPUT|百度搜索框
2020-08-25 17:50:33,517 [INFO]: #  Run The Step: 2|INPUT|百度搜索页-百度搜索框 Success
2020-08-25 17:50:33,818 [INFO]: #  Run The Step: 3|CLICK|百度搜索按钮
2020-08-25 17:50:34,378 [INFO]: #  Run The Step: 3|CLICK|百度搜索页-百度搜索按钮 Success
2020-08-25 17:50:35,190 [INFO]: #  ****  用例执行完成  ****
2020-08-25 17:52:34,694 [INFO]: #  **** 从Excel导入用例套件成功 ****
2020-08-25 17:52:34,694 [INFO]: #  **** 解析用例成功 ****
2020-08-25 17:52:34,694 [INFO]: #  -------- Run The TestCase：test-1 打开百度
2020-08-25 17:52:34,694 [INFO]: #  Run The Step: 1|OPEN|百度搜索链接
2020-08-25 17:52:36,869 [INFO]: #  Run The Step: 1|OPEN|百度搜索页-百度搜索链接 Success
2020-08-25 17:52:37,170 [INFO]: #  Run The Step: 2|INPUT|百度搜索框
2020-08-25 17:52:37,768 [INFO]: #  Run The Step: 2|INPUT|百度搜索页-百度搜索框 Success
2020-08-25 17:52:38,069 [INFO]: #  Run The Step: 3|CLICK|百度搜索按钮
2020-08-25 17:52:38,618 [INFO]: #  Run The Step: 3|CLICK|百度搜索页-百度搜索按钮 Success
2020-08-25 17:52:39,428 [INFO]: #  ****  用例执行完成  ****
